# -*- coding: utf-8 -*-
from odoo import models, fields, api, _
from odoo.exceptions import UserError
import logging
_logger = logging.getLogger(__name__)


class StockWarehouse(models.Model):
    _inherit = 'stock.warehouse'

    document_class_id = fields.Many2one(
            'sii.document_class',
            string='Document Type',
            domain=[('document_type', '=', 'stock_picking')]
        )
    sequence_id = fields.Many2one(
            'ir.sequence',
            string='Entry Sequence',
            help="""This field contains the information related to the numbering \
            of the documents entries of this document type.""",
            domain=[('sii_document_class_id.document_type', '=', 'stock_picking')]
        )
    sucursal_id = fields.Many2one(
        'sii.sucursal',
        string="Sucursal SII"
    )
    sii_code = fields.Char(
        related='sucursal_id.sii_code',
        string="C칩digo de Sucursal SII",
    )
    restore_mode = fields.Boolean(
            string="Modo Restauraci칩n",
            default=False,
        )
    company_activity_ids = fields.Many2many(
        "partner.activities",
        related="company_id.company_activities_ids")
    acteco_ids = fields.Many2many(
            'partner.activities',
            string="C칩digo de Actividades",
        )

    @api.onchange('acteco_ids')
    def limitar_actecos(self):
        if len(self.acteco_ids) > 4:
            raise UserError("Deben ser m치ximo 4 actecos")
